<?xml version="1.0"?>
<robot name="arm_3dof">
  <!-- Base Link -->
  <link name="base_link">
    <visual>
      <geometry><cylinder length="0.05" radius="0.05"/></geometry>
    </visual>
  </link>

  <!-- Link 1 -->
  <link name="link1">
    <visual>
      <origin xyz="0 0 0.15" rpy="0 0 0"/>
      <geometry><cylinder length="1.12" radius="0.05"/></geometry>
    </visual>
  </link>

  <!-- Joint 1: Base to Link1 (rotate around Z) -->
  <joint name="joint1" type="revolute">
    <parent link="base_link"/>
    <child link="link1"/>
    <origin xyz="0 0 0.025" rpy="0 0 0"/>
    <axis xyz="0 0 1"/>
    <limit lower="-3.14" upper="3.14" effort="10" velocity="1"/>
  </joint>

  <!-- Link 2 -->
  <link name="link2">
    <visual>
      <origin xyz="0 0 0.125" rpy="0 0 0"/>
      <geometry><cylinder length="1.4" radius="0.05"/></geometry>
    </visual>
  </link>

  <!-- Joint 2: Link1 to Link2 (rotate around Y - shoulder) -->
  <joint name="joint2" type="revolute">
    <parent link="link1"/>
    <child link="link2"/>
    <origin xyz="0 0 0.3" rpy="0 0 0"/>
    <axis xyz="1 0 0"/>
    <limit lower="-1.57" upper="1.57" effort="10" velocity="1"/>
  </joint>

  <!-- Link 3 (End Effector) -->
  <link name="link3">
    <visual>
      <origin xyz="0 0 0.1" rpy="0 0 0"/>
      <geometry><cylinder length="0.6" radius="0.015"/></geometry>
    </visual>
  </link>

  <!-- Joint 3: Link2 to Link3 (rotate around Y - elbow) -->
  <joint name="joint3" type="revolute">
    <parent link="link2"/>
    <child link="link3"/>
    <origin xyz="0 0 0.25" rpy="0 0 0"/>
    <axis xyz="0 1 0"/>
    <limit lower="-2.0" upper="2.0" effort="10" velocity="1"/>
  </joint>

  <!-- End Effector Frame -->
  <link name="end_effector"/>
  <joint name="ee_joint" type="fixed">
    <parent link="link3"/>
    <child link="end_effector"/>
    <origin xyz="0 0 0.2" rpy="0 0 0"/>
  </joint>
</robot>
