<?xml version="1.0" encoding="UTF-8"?>
<!-- Generated by urdf_generator.py -->
<!-- StackConfig + RoboticArmGeometry → parametric URDF -->
<!-- Coordinate frame: LAR origin, +Z=nadir, +X=North, +Y=East -->
<robot name="thruster_arm_stack">
  <link name="world"/>
  <link name="LAR_interface"/>
  <link name="client_bus">
    <visual>
      <geometry><box size="2.5 2.2 3"/></geometry>
      <material name=""><color rgba="0.600 0.600 0.800 1.000"/></material>
    </visual>
    <collision>
      <geometry><box size="2.5 2.2 3"/></geometry>
    </collision>
    <inertial>
      <origin xyz="0 0 0" rpy="0 0 0"/>
      <mass value="2500.000000"/>
      <inertia ixx="2.883333e+03" ixy="0.000000e+00" ixz="0.000000e+00" iyy="3.177083e+03" iyz="0.000000e+00" izz="2.310417e+03"/>
    </inertial>
  </link>
  <link name="client_panel_north">
    <visual>
      <geometry><box size="16 2.2 0.02"/></geometry>
      <material name=""><color rgba="0.200 0.600 0.200 1.000"/></material>
    </visual>
    <collision>
      <geometry><box size="16 2.2 0.02"/></geometry>
    </collision>
    <inertial>
      <origin xyz="0 0 0" rpy="0 0 0"/>
      <mass value="50.000000"/>
      <inertia ixx="2.016667e+01" ixy="0.000000e+00" ixz="0.000000e+00" iyy="1.066667e+03" iyz="0.000000e+00" izz="1.086833e+03"/>
    </inertial>
  </link>
  <link name="client_panel_south">
    <visual>
      <geometry><box size="16 2.2 0.02"/></geometry>
      <material name=""><color rgba="0.200 0.600 0.200 1.000"/></material>
    </visual>
    <collision>
      <geometry><box size="16 2.2 0.02"/></geometry>
    </collision>
    <inertial>
      <origin xyz="0 0 0" rpy="0 0 0"/>
      <mass value="50.000000"/>
      <inertia ixx="2.016667e+01" ixy="0.000000e+00" ixz="0.000000e+00" iyy="1.066667e+03" iyz="0.000000e+00" izz="1.086833e+03"/>
    </inertial>
  </link>
  <link name="antenna_E1">
    <visual>
      <geometry><mesh filename="file://urdf_output/meshes/antenna_E1_d2.20.stl" scale="1 1 1"/></geometry>
      <material name=""><color rgba="0.800 0.800 0.200 1.000"/></material>
    </visual>
    <collision>
      <geometry><cylinder radius="1.100000" length="0.275000"/></geometry>
    </collision>
    <inertial>
      <origin xyz="0 0 0" rpy="0 0 0"/>
      <mass value="20.000000"/>
      <inertia ixx="6.050000e+00" ixy="0.000000e+00" ixz="0.000000e+00" iyy="6.050000e+00" iyz="0.000000e+00" izz="1.210000e+01"/>
    </inertial>
  </link>
  <link name="antenna_E2">
    <visual>
      <geometry><mesh filename="file://urdf_output/meshes/antenna_E2_d2.20.stl" scale="1 1 1"/></geometry>
      <material name=""><color rgba="0.800 0.800 0.200 1.000"/></material>
    </visual>
    <collision>
      <geometry><cylinder radius="1.100000" length="0.275000"/></geometry>
    </collision>
    <inertial>
      <origin xyz="0 0 0" rpy="0 0 0"/>
      <mass value="20.000000"/>
      <inertia ixx="6.050000e+00" ixy="0.000000e+00" ixz="0.000000e+00" iyy="6.050000e+00" iyz="0.000000e+00" izz="1.210000e+01"/>
    </inertial>
  </link>
  <link name="antenna_W1">
    <visual>
      <geometry><mesh filename="file://urdf_output/meshes/antenna_W1_d2.50.stl" scale="1 1 1"/></geometry>
      <material name=""><color rgba="0.800 0.800 0.200 1.000"/></material>
    </visual>
    <collision>
      <geometry><cylinder radius="1.250000" length="0.312500"/></geometry>
    </collision>
    <inertial>
      <origin xyz="0 0 0" rpy="0 0 0"/>
      <mass value="20.000000"/>
      <inertia ixx="7.812500e+00" ixy="0.000000e+00" ixz="0.000000e+00" iyy="7.812500e+00" iyz="0.000000e+00" izz="1.562500e+01"/>
    </inertial>
  </link>
  <link name="antenna_W2">
    <visual>
      <geometry><mesh filename="file://urdf_output/meshes/antenna_W2_d2.50.stl" scale="1 1 1"/></geometry>
      <material name=""><color rgba="0.800 0.800 0.200 1.000"/></material>
    </visual>
    <collision>
      <geometry><cylinder radius="1.250000" length="0.312500"/></geometry>
    </collision>
    <inertial>
      <origin xyz="0 0 0" rpy="0 0 0"/>
      <mass value="20.000000"/>
      <inertia ixx="7.812500e+00" ixy="0.000000e+00" ixz="0.000000e+00" iyy="7.812500e+00" iyz="0.000000e+00" izz="1.562500e+01"/>
    </inertial>
  </link>
  <link name="servicer_bus">
    <visual>
      <geometry><box size="0.9 1.52 0.8"/></geometry>
      <material name=""><color rgba="0.700 0.400 0.100 1.000"/></material>
    </visual>
    <collision>
      <geometry><box size="0.9 1.52 0.8"/></geometry>
    </collision>
    <inertial>
      <origin xyz="0 0 0" rpy="0 0 0"/>
      <mass value="735.000000"/>
      <inertia ixx="1.807120e+02" ixy="0.000000e+00" ixz="0.000000e+00" iyy="8.881250e+01" iyz="0.000000e+00" izz="1.911245e+02"/>
    </inertial>
  </link>
  <link name="thruster_arm_base"/>
  <link name="arm_link_1">
    <visual>
      <origin xyz="0.56 0 0" rpy="0 1.5707963 0"/>
      <geometry><cylinder radius="0.050000" length="1.120000"/></geometry>
      <material name=""><color rgba="0.900 0.500 0.100 1.000"/></material>
    </visual>
    <collision>
      <origin xyz="0.56 0 0" rpy="0 1.5707963 0"/>
      <geometry><cylinder radius="0.050000" length="1.120000"/></geometry>
    </collision>
    <inertial>
      <origin xyz="0.56 0 0" rpy="0 0 0"/>
      <mass value="10.000000"/>
      <inertia ixx="1.250000e-02" ixy="0.000000e+00" ixz="0.000000e+00" iyy="1.051583e+00" iyz="0.000000e+00" izz="1.051583e+00"/>
    </inertial>
  </link>
  <link name="arm_link_2">
    <visual>
      <origin xyz="0.7 0 0" rpy="0 1.5707963 0"/>
      <geometry><cylinder radius="0.050000" length="1.400000"/></geometry>
      <material name=""><color rgba="0.900 0.500 0.100 1.000"/></material>
    </visual>
    <collision>
      <origin xyz="0.7 0 0" rpy="0 1.5707963 0"/>
      <geometry><cylinder radius="0.050000" length="1.400000"/></geometry>
    </collision>
    <inertial>
      <origin xyz="0.7 0 0" rpy="0 0 0"/>
      <mass value="10.000000"/>
      <inertia ixx="1.250000e-02" ixy="0.000000e+00" ixz="0.000000e+00" iyy="1.639583e+00" iyz="0.000000e+00" izz="1.639583e+00"/>
    </inertial>
  </link>
  <link name="thruster_bracket">
    <visual>
      <origin xyz="0.175 0 0" rpy="0 1.5707963 0"/>
      <geometry><cylinder radius="0.040000" length="0.350000"/></geometry>
      <material name=""><color rgba="0.800 0.200 0.200 1.000"/></material>
    </visual>
    <collision>
      <origin xyz="0.175 0 0" rpy="0 1.5707963 0"/>
      <geometry><cylinder radius="0.040000" length="0.350000"/></geometry>
    </collision>
    <inertial>
      <origin xyz="0.175 0 0" rpy="0 0 0"/>
      <mass value="3.000000"/>
      <inertia ixx="2.400000e-03" ixy="0.000000e+00" ixz="0.000000e+00" iyy="3.182500e-02" iyz="0.000000e+00" izz="3.182500e-02"/>
    </inertial>
  </link>
  <link name="thruster_frame">
    <visual>
      <geometry><box size="0.05 0.1 0.02"/></geometry>
      <material name=""><color rgba="1.000 0.000 0.000 1.000"/></material>
    </visual>
    <collision>
      <geometry><box size="0.05 0.1 0.02"/></geometry>
    </collision>
    <inertial>
      <origin xyz="0 0 0" rpy="0 0 0"/>
      <mass value="0.001000"/>
      <inertia ixx="1.000000e-06" ixy="0.000000e+00" ixz="0.000000e+00" iyy="1.000000e-06" iyz="0.000000e+00" izz="1.000000e-06"/>
    </inertial>
  </link>
  <joint name="world_to_LAR" type="fixed">
    <parent link="world"/>
    <child link="LAR_interface"/>
    <origin xyz="0 0 0" rpy="0 0 0"/>
  </joint>
  <joint name="LAR_to_client_bus" type="fixed">
    <parent link="LAR_interface"/>
    <child link="client_bus"/>
    <origin xyz="0 0 1.5" rpy="0 0 0"/>
  </joint>
  <joint name="client_bus_to_panel_north" type="fixed">
    <parent link="client_bus"/>
    <child link="client_panel_north"/>
    <origin xyz="9.25 1 0" rpy="0 0 0"/>
  </joint>
  <joint name="client_bus_to_panel_south" type="fixed">
    <parent link="client_bus"/>
    <child link="client_panel_south"/>
    <origin xyz="-9.25 1 0" rpy="0 0 0"/>
  </joint>
  <joint name="client_bus_to_antenna_E1" type="fixed">
    <parent link="client_bus"/>
    <child link="antenna_E1"/>
    <origin xyz="-0.75 1.1 0.8" rpy="0 0 0"/>
  </joint>
  <joint name="client_bus_to_antenna_E2" type="fixed">
    <parent link="client_bus"/>
    <child link="antenna_E2"/>
    <origin xyz="0.75 1.1 0.8" rpy="0 0 0"/>
  </joint>
  <joint name="client_bus_to_antenna_W1" type="fixed">
    <parent link="client_bus"/>
    <child link="antenna_W1"/>
    <origin xyz="-0.75 -1.1 0.8" rpy="0 0 0"/>
  </joint>
  <joint name="client_bus_to_antenna_W2" type="fixed">
    <parent link="client_bus"/>
    <child link="antenna_W2"/>
    <origin xyz="0.75 -1.1 0.8" rpy="0 0 0"/>
  </joint>
  <joint name="LAR_to_servicer_bus" type="fixed">
    <parent link="LAR_interface"/>
    <child link="servicer_bus"/>
    <origin xyz="0 0 -1.25" rpy="0 0 0"/>
  </joint>
  <joint name="servicer_to_arm_base" type="fixed">
    <parent link="servicer_bus"/>
    <child link="thruster_arm_base"/>
    <origin xyz="0 0 0.4" rpy="0 0 0"/>
  </joint>
  <joint name="J1_shoulder_yaw" type="revolute">
    <parent link="thruster_arm_base"/>
    <child link="arm_link_1"/>
    <origin xyz="0 0 0" rpy="0 0 0"/>
    <axis xyz="0 0 1"/>
    <limit lower="0.00000000" upper="4.71238898" effort="200.0" velocity="1.0000"/>
    <dynamics damping="0.1" friction="0.0"/>
  </joint>
  <joint name="J2_elbow_pitch" type="revolute">
    <parent link="arm_link_1"/>
    <child link="arm_link_2"/>
    <origin xyz="1.12 0 0" rpy="0 0 0"/>
    <axis xyz="0 1 0"/>
    <limit lower="0.00000000" upper="4.10152374" effort="200.0" velocity="1.0000"/>
    <dynamics damping="0.1" friction="0.0"/>
  </joint>
  <joint name="J3_wrist_pitch" type="revolute">
    <parent link="arm_link_2"/>
    <child link="thruster_bracket"/>
    <origin xyz="1.4 0 0" rpy="0 0 0"/>
    <axis xyz="0 1 0"/>
    <limit lower="-0.62831853" upper="1.72787596" effort="200.0" velocity="1.0000"/>
    <dynamics damping="0.1" friction="0.0"/>
  </joint>
  <joint name="bracket_to_thruster_frame" type="fixed">
    <parent link="thruster_bracket"/>
    <child link="thruster_frame"/>
    <origin xyz="0.35 0 0" rpy="0 0 0"/>
  </joint>
</robot>